Workbook

Sheet Questions
B1: You are the data analyst of a luxury car dealership. You were assigned with the following tasks: | P1: All rights reserved (c)
A2: 1 | B2: What's the most popular car manufacturer? | P2: Excel-Practice-Online
A3: 2 | B3: What's the most popular manufacturing country (Refer to "Manufacturing country" sheet)?
A4: 3 | B4: What's the least popular color for cars?
A5: 4 | B5: What's the average price per owner?
B7: Car | C7: Manufacturer | D7: Unique Manuafacturers | E7: Unique Counts | F7: Year | G7: KM Driven | H7: Color | I7: Unique Colors | J7: Unique Color counts | K7: Transimission | L7: Owner | M7: Price (USD) | N7: Unique Owners | O7: Avg Price
B8: BMW X5 | C8: =LEFT(B8:B25,find(" ",B8)-1) -> BMW | D8: {=Unique(C8:C25)} -> BMW | E8: =countif(C8:C25,D8) -> 7 | F8: 2012 | G8: 342358 | H8: White | I8: {=unique($H$8:$H$25)} -> White | J8: =countif($H$8:$H$25,I8) -> 6 | K8: Automatic | L8: 1st owner | M8: 15400 | N8: {=Unique($L$8:$L$25)} -> 1st owner | O8: =AVerageif($L$8:$L$25,N8,$M$8:$M$25) -> 36513.667
B9: Audi A3 | C9: =LEFT(B9:B26,find(" ",B9)-1) -> Audi | D9: Audi | E9: =countif(C9:C26,D9) -> 2 | F9: 2017 | G9: 130000 | H9: Red | I9: Red | J9: =countif($H$8:$H$25,I9) -> 4 | K9: Manual | L9: 2nd owner | M9: 24321 | N9: 2nd owner | O9: =AVerageif($L$8:$L$25,N9,$M$8:$M$25) -> 30718
B10: Mercedes S-Class | C10: =LEFT(B10:B27,find(" ",B10)-1) -> Mercedes | D10: Mercedes | E10: =countif(C10:C27,D10) -> 2 | F10: 2020 | G10: 92450 | H10: Black | I10: Black | J10: =countif($H$8:$H$25,I10) -> 4 | K10: Automatic | L10: 3rd owner | M10: 102342 | N10: 3rd owner | O10: =AVerageif($L$8:$L$25,N10,$M$8:$M$25) -> 63746.333
B11: BMW X5 | C11: =LEFT(B11:B28,find(" ",B11)-1) -> BMW | D11: Lexus | E11: =countif(C11:C28,D11) -> 3 | F11: 2020 | G11: 76240 | H11: White | I11: Blue | J11: =countif($H$8:$H$25,I11) -> 3 | K11: Automatic | L11: 2nd owner | M11: 55272 | N11: 4th owner | O11: =AVerageif($L$8:$L$25,N11,$M$8:$M$25) -> 22520
B12: BMW X3 | C12: =LEFT(B12:B29,find(" ",B12)-1) -> BMW | D12: Tesla | E12: =countif(C12:C29,D12) -> 1 | F12: 2021 | G12: 17283 | H12: White | I12: Yellow | J12: =countif($H$8:$H$25,I12) -> 1 | K12: Manual | L12: 1st owner | M12: 42000
B13: Lexus RX350 | C13: =LEFT(B13:B30,find(" ",B13)-1) -> Lexus | D13: Volvo | E13: =countif(C13:C30,D13) -> 1 | F13: 2020 | G13: 98312 | H13: Red | K13: Automatic | L13: 3rd owner | M13: 51292
B14: BMW X3 | C14: =LEFT(B14:B31,find(" ",B14)-1) -> BMW | D14: Cadillac | E14: =countif(C14:C31,D14) -> 1 | F14: 2018 | G14: 156784 | H14: Blue | K14: Manual | L14: 3rd owner | M14: 37605
B15: BMW X5 | C15: =LEFT(B15:B32,find(" ",B15)-1) -> BMW | D15: Jaguar | E15: =countif(C15:C32,D15) -> 1 | F15: 2019 | G15: 52034 | H15: Blue | K15: Automatic | L15: 1st owner | M15: 45000
B16: BMW 3 Series | C16: =LEFT(B16:B33,find(" ",B16)-1) -> BMW | F16: 2011 | G16: 205204 | H16: Red | K16: Automatic | L16: 2nd owner | M16: 13241
B17: Mercedes S-Class | C17: =LEFT(B17:B34,find(" ",B17)-1) -> Mercedes | F17: 2014 | G17: 152985 | H17: Black | K17: Automatic | L17: 2nd owner | M17: 49344
B18: Tesla Model 3 | C18: =LEFT(B18:B36,find(" ",B18)-1) -> Tesla | F18: 2018 | G18: 76429 | H18: Yellow | K18: Automatic | L18: 1st owner | M18: 52432
B19: Volvo XC90 | C19: =LEFT(B19:B37,find(" ",B19)-1) -> Volvo | F19: 2013 | G19: 254028 | H19: Black | K19: Manual | L19: 2nd owner | M19: 17452
B20: Audi Q7 | C20: =LEFT(B20:B39,find(" ",B20)-1) -> Audi | F20: 2014 | G20: 45832 | H20: White | K20: Manual | L20: 1st owner | M20: 23250
B21: Cadillac XT5 | C21: =LEFT(B21:B40,find(" ",B21)-1) -> Cadillac | F21: 2018 | G21: 67591 | H21: Blue | K21: Automatic | L21: 2nd owner | M21: 32420
B22: Jaguar XF | C22: =LEFT(B22:B42,find(" ",B22)-1) -> Jaguar | F22: 2013 | G22: 85320 | H22: White | K22: Automatic | L22: 2nd owner | M22: 18454
B23: Lexus RX350 | C23: =LEFT(B23:B43,find(" ",B23)-1) -> Lexus | F23: 2016 | G23: 5000 | H23: White | K23: Automatic | L23: 1st owner | M23: 41000
B24: BMW 428i | C24: =LEFT(B24:B44,find(" ",B24)-1) -> BMW | F24: 2017 | G24: 92450 | H24: Red | K24: Manual | L24: 2nd owner | M24: 35240
B25: Lexus RX350 | C25: =LEFT(B25:B45,find(" ",B25)-1) -> Lexus | F25: 2015 | G25: 130000 | H25: Black | K25: Automatic | L25: 4th owner | M25: 22520
B31: Data Audit & Cleaning Notes
B33: Source Reconciliation:.
B34: Cross-referenced raw data against the Solution tab to identify missing entries
B36: Formatting Fixes:
B37: Applied TRIM and LEFT functions to resolve "dirty" strings in the Manufacturer and Color columns.
B39: Population Accuracy:
B40: Corrected the total record count to 18 (the original manual key only accounted for 16), ensuring all averages are 100% accurate.
B42: Integrity:
B43: All formulas now pull from "Cleaned" columns to prevent errors caused by hidden whitespaces.

Sheet Manufacturing country
A1: Company | B1: Country | C1: Manufacturer | D1: Country | F1: Unique Country | G1: Count By Country
A2: BMW | B2: Germany | C2: BMW | D2: =xlookup(C2,A$2:A$9,$B$2:$B$9) -> Germany | F2: {=unique(D2:D19)} -> Germany | G2: =countif($D$2:$D$19,F2) -> 11
A3: Audi | B3: Germany | C3: Audi | D3: =xlookup(C3,A$2:A$9,$B$2:$B$9) -> Germany | F3: Japan | G3: =countif($D$2:$D$19,F3) -> 3
A4: Tesla | B4: USA | C4: Mercedes | D4: =xlookup(C4,A$2:A$9,$B$2:$B$9) -> Germany | F4: USA | G4: =countif($D$2:$D$19,F4) -> 2
A5: Jaguar | B5: UK | C5: BMW | D5: =xlookup(C5,A$2:A$9,$B$2:$B$9) -> Germany | F5: Sweden | G5: =countif($D$2:$D$19,F5) -> 1
A6: Mercedes | B6: Germany | C6: BMW | D6: =xlookup(C6,A$2:A$9,$B$2:$B$9) -> Germany | F6: UK | G6: =countif($D$2:$D$19,F6) -> 1
A7: Volvo | B7: Sweden | C7: Lexus | D7: =xlookup(C7,A$2:A$9,$B$2:$B$9) -> Japan
A8: Cadillac | B8: USA | C8: BMW | D8: =xlookup(C8,A$2:A$9,$B$2:$B$9) -> Germany
A9: Lexus | B9: Japan | C9: BMW | D9: =xlookup(C9,A$2:A$9,$B$2:$B$9) -> Germany
C10: BMW | D10: =xlookup(C10,A$2:A$9,$B$2:$B$9) -> Germany
C11: Mercedes | D11: =xlookup(C11,A$2:A$9,$B$2:$B$9) -> Germany
C12: Tesla | D12: =xlookup(C12,A$2:A$9,$B$2:$B$9) -> USA
C13: Volvo | D13: =xlookup(C13,A$2:A$9,$B$2:$B$9) -> Sweden
C14: Audi | D14: =xlookup(C14,A$2:A$9,$B$2:$B$9) -> Germany
C15: Cadillac | D15: =xlookup(C15,A$2:A$9,$B$2:$B$9) -> USA
C16: Jaguar | D16: =xlookup(C16,A$2:A$9,$B$2:$B$9) -> UK
C17: Lexus | D17: =xlookup(C17,A$2:A$9,$B$2:$B$9) -> Japan
C18: BMW | D18: =xlookup(C18,A$2:A$9,$B$2:$B$9) -> Germany
C19: Lexus | D19: =xlookup(C19,A$2:A$9,$B$2:$B$9) -> Japan

Sheet Solution
B1: Car | C1: Year | D1: KM Driven | E1: Color | F1: Transimission | G1: Owner | H1: Price (USD)
B2: BMW X5 | C2: 2012 | D2: 342358 | E2: White | F2: Automatic | G2: 1st owner | H2: $15400
B3: Audi A3 | C3: 2017 | D3: 130000 | E3: Red | F3: Manual | G3: 2nd owner | H3: $24321
B4: Mercedes S-Class | C4: 2020 | D4: 92450 | E4: Black | F4: Automatic | G4: 3rd owner | H4: $102342
B5: BMW X5 | C5: 2020 | D5: 76240 | E5: White | F5: Automatic | G5: 2nd owner | H5: $55272
B6: BMW X3 | C6: 2021 | D6: 17283 | E6: White | F6: Manual | G6: 1st owner | H6: $42000
B7: Lexus RX350 | C7: 2020 | D7: 98312 | E7: Red | F7: Automatic | G7: 3rd owner | H7: $51292
B8: BMW X3 | C8: 2018 | D8: 156784 | E8: Blue | F8: Manual | G8: 3rd owner | H8: $37605
B9: BMW X5 | C9: 2019 | D9: 52034 | E9: Blue | F9: Automatic | G9: 1st owner | H9: $45000
B10: BMW 3 Series | C10: 2011 | D10: 205204 | E10: Red | F10: Automatic | G10: 2nd owner | H10: $13241
B11: Mercedes S-Class | C11: 2014 | D11: 152985 | E11: Black | F11: Automatic | G11: 2nd owner | H11: $49344
B12: Tesla Model 3 | C12: 2018 | D12: 76429 | E12: Yellow | F12: Automatic | G12: 1st owner | H12: $52432
B13: Volvo XC90 | C13: 2013 | D13: 254028 | E13: Black | F13: Manual | G13: 2nd owner | H13: $17452
... B19: Lexus RX350 | C19: 2015 | D19: 130000 | E19: Black | F19: Automatic | G19: 4th owner | H19: $22520
B21: You are the data analyst of a luxury car dealership. You were assigned with the following tasks:
A22: 1 | B22: What's the most popular car manufacturer?
B24: Answer:
B25: To answer this, we must first extract the manufacturer's name from the "Car" column, as there are manufacturers that have more than one model listed.
B26: To do this, we can add a new column, and apply the LEFT function, combined with a FIND function, to extract only the first word from "Car":
B28: Car | C28: Year | D28: KM Driven | E28: Color | F28: Transimission | G28: Owner | H28: Price (USD) | I28: Manufacturer
B29: BMW X5 | C29: 2012 | D29: 342358 | E29: White | F29: Automatic | G29: 1st owner | H29: $15400 | I29: =LEFT(B29,FIND(" ",B29)-1) -> BMW | J29: =FORMULATEXT(I29) -> =LEFT(B29,FIND(" ",B29)-1)
B30: Audi A3 | C30: 2017 | D30: 130000 | E30: Red | F30: Manual | G30: 2nd owner | H30: $24321 | I30: =LEFT(B30,FIND(" ",B30)-1) -> Audi | J30: =FORMULATEXT(I30) -> =LEFT(B30,FIND(" ",B30)-1)
B31: Mercedes S-Class | C31: 2020 | D31: 92450 | E31: Black | F31: Automatic | G31: 3rd owner | H31: $102342 | I31: =LEFT(B31,FIND(" ",B31)-1) -> Mercedes | J31: =FORMULATEXT(I31) -> =LEFT(B31,FIND(" ",B31)-1)
B32: BMW X5 | C32: 2020 | D32: 76240 | E32: White | F32: Automatic | G32: 2nd owner | H32: $55272 | I32: =LEFT(B32,FIND(" ",B32)-1) -> BMW | J32: =FORMULATEXT(I32) -> =LEFT(B32,FIND(" ",B32)-1)
B33: BMW X3 | C33: 2021 | D33: 17283 | E33: White | F33: Manual | G33: 1st owner | H33: $42000 | I33: =LEFT(B33,FIND(" ",B33)-1) -> BMW | J33: =FORMULATEXT(I33) -> =LEFT(B33,FIND(" ",B33)-1)
B34: Lexus RX350 | C34: 2020 | D34: 98312 | E34: Red | F34: Automatic | G34: 3rd owner | H34: $51292 | I34: =LEFT(B34,FIND(" ",B34)-1) -> Lexus | J34: =FORMULATEXT(I34) -> =LEFT(B34,FIND(" ",B34)-1)
B35: BMW X3 | C35: 2018 | D35: 156784 | E35: Blue | F35: Manual | G35: 3rd owner | H35: $37605 | I35: =LEFT(B35,FIND(" ",B35)-1) -> BMW | J35: =FORMULATEXT(I35) -> =LEFT(B35,FIND(" ",B35)-1)
B36: BMW X5 | C36: 2019 | D36: 52034 | E36: Blue | F36: Automatic | G36: 1st owner | H36: $45000 | I36: =LEFT(B36,FIND(" ",B36)-1) -> BMW | J36: =FORMULATEXT(I36) -> =LEFT(B36,FIND(" ",B36)-1)
B37: BMW 3 Series | C37: 2011 | D37: 205204 | E37: Red | F37: Automatic | G37: 2nd owner | H37: $13241 | I37: =LEFT(B37,FIND(" ",B37)-1) -> BMW | J37: =FORMULATEXT(I37) -> =LEFT(B37,FIND(" ",B37)-1)
B38: Mercedes S-Class | C38: 2014 | D38: 152985 | E38: Black | F38: Automatic | G38: 2nd owner | H38: $49344 | I38: =LEFT(B38,FIND(" ",B38)-1) -> Mercedes | J38: =FORMULATEXT(I38) -> =LEFT(B38,FIND(" ",B38)-1)
B39: Tesla Model 3 | C39: 2018 | D39: 76429 | E39: Yellow | F39: Automatic | G39: 1st owner | H39: $52432 | I39: =LEFT(B39,FIND(" ",B39)-1) -> Tesla | J39: =FORMULATEXT(I39) -> =LEFT(B39,FIND(" ",B39)-1)
B40: Volvo XC90 | C40: 2013 | D40: 254028 | E40: Black | F40: Manual | G40: 2nd owner | H40: $17452 | I40: =LEFT(B40,FIND(" ",B40)-1) -> Volvo | J40: =FORMULATEXT(I40) -> =LEFT(B40,FIND(" ",B40)-1)
... B46: Lexus RX350 | C46: 2015 | D46: 130000 | E46: Black | F46: Automatic | G46: 4th owner | H46: $22520 | I46: =LEFT(B46,FIND(" ",B46)-1) -> Lexus | J46: =FORMULATEXT(I46) -> =LEFT(B46,FIND(" ",B46)-1)
B48: The LEFT function extracts characters from the left side of the cell. How many characters? This is determined in the 2nd argument here - And instead of writing a specific character position,
B49: we are using the FIND function to find the first space character position, and then subtract 1 (as we are not interested in extracting the space itself, only what's before.
B51: Click here to learn and practice the LEFT function
B52: Click here to learn and practice the FIND function
B54: Now that we have extracted the Manufacturer's name, we can check who's the most popular one:
B55: Let's use a UNIQUE & COUNTIF for this example:
B57: Manufacturer | C57: Count
...
